Workbook

Sheet Simulator
B1: THE SUMMER CLUB — SCENARIO SIMULATOR
B2: Change the yellow cells to see how your numbers shift instantly
B4: YOUR INPUTS
F5: TOTAL REVENUE
B6: Number of kids | C6: 18 | D6: Change this to see break-even | F6: =C28
B7: Early bird price | C7: 21000 | D7: Price for first 25 families
B8: Regular price | C8: 24500 | D8: Full price after early bird | F8: TOTAL COSTS
B9: % paying early bird | C9: 0.6 | D9: What portion gets the discount | F9: =C40
B11: Venue rent (per month) | C11: 45000 | D11: Half-day (9-1pm), gated campus, AC, South BLR | F11: NET PROFIT
B12: Venue deposit (refundable) | C12: 90000 | D12: 2 months deposit (refundable after camp) | F12: =C42
B13: Staff cost (per month, total) | C13: 95000 | D13: Instructor ₹35K + ₹30K + Helper ₹18K + First aid ₹12K
B14: Materials per child (7 weeks) | C14: 3500 | D14: ₹500/child/week avg across all 7 themes | F14: MARGIN
B15: Snacks per child per day | C15: 55 | D15: Quality fruit + juice, ₹55/child/day | F15: =C43
B16: Per-child ops (tshirt, cert, etc) | C16: 1000 | D16: T-shirt ₹450 + Scrapbook ₹300 + Cert ₹150 + Tag ₹100
B17: Marketing budget | C17: 15000 | D17: Flyers, posters, Instagram boost, WhatsApp tools | F17: BREAK-EVEN KIDS
B18: Insurance + first aid kit | C18: 15000 | D18: Group activity insurance + first aid kit + safety gear | F18: =ROUNDUP((C31+C32+C36+C37+((C31+C32+C36+C37)*C19)) / ((C7*C9+C8*(1-C9)) - (C14+C15*35+C16) - (C14+C15*35+C16)*C19), 0)
B19: Buffer % | C19: 0.1 | D19: Safety margin
F20: COST PER CHILD
B21: RESULTS | F21: =IF(C6>0,C40/C6,0)
B23: REVENUE
B24: Early bird kids | C24: =ROUND(C6*C9,0)
B25: Regular kids | C25: =C6-C24
B26: Early bird revenue | C26: =C24*C7
B27: Regular revenue | C27: =C25*C8
B28: Total Revenue | C28: =C26+C27
B30: COSTS
B31: Venue (rent × 2 + deposit) | C31: =C11*2+C12
B32: Staff (× 2 months) | C32: =C13*2
B33: Materials (all kids) | C33: =C14*C6
B34: Snacks (all kids × 35 days) | C34: =C15*C6*35
B35: Per-child ops (all kids) | C35: =C16*C6
B36: Marketing | C36: =C17
B37: Insurance + ops | C37: =C18
B38: Subtotal | C38: =SUM(C31:C37)
B39: Buffer | C39: =C38*C19
B40: Total Costs | C40: =C38+C39
B42: NET PROFIT / (LOSS) | C42: =C28-C40
B43: Margin % | C43: =IF(C28>0,C42/C28,0)
B45: SENSITIVITY: PROFIT BY NUMBER OF KIDS
B46: # Kids | C46: Revenue | D46: Total Costs | E46: Profit | F46: Margin
...

Sheet Revenue
A1: THE SUMMER CLUB — REVENUE SCENARIOS
A2: 7-week programme · April 14 – May 30, 2026
A4: ASSUMPTIONS
A6: Early bird price (per child) | B6: 21000
A7: Regular price (per child) | B7: 24500
A8: Early bird mix | B8: 0.6
A9: Regular mix | B9: =1-B8
A11: SCENARIOS
B12: Scenario A (Conservative) | C12: Scenario B (Target) | D12: Scenario C (Stretch)
A13: Total kids | B13: 12 | C13: 18 | D13: 24
A14: Early bird kids | B14: =B13*B8 | C14: =C13*B8 | D14: =D13*B8
A15: Regular price kids | B15: =B13-B14 | C15: =C13-C14 | D15: =D13-D14
A17: Early bird revenue | B17: =B14*B6 | C17: =C14*B6 | D17: =D14*B6
A18: Regular revenue | B18: =B15*B7 | C18: =C15*B7 | D18: =D15*B7
A20: TOTAL REVENUE | B20: =B17+B18 | C20: =C17+C18 | D20: =D17+D18
A21: Revenue per child | B21: =B20/B13 | C21: =C20/C13 | D21: =D20/D13

Sheet Costs
A1: THE SUMMER CLUB — DETAILED COSTS
A2: Based on target batch of 18 kids
A4: Item | B4: Monthly / Unit | C4: Duration / Qty | D4: Total | E4: Notes
A5: VENUE
A6: Activity space rental | B6: 45000 | C6: 2 months | D6: =B6*2 | E6: Community hall / co-working space, mornings only
A7: Security deposit (refundable) | B7: 90000 | C7: 1 | D7: =B7 | E7: Typically 1 month rent
A9: STAFF
A10: Lead instructor #1 | B10: 35000 | C10: 2 months | D10: =B10*2 | E10: Art/science background, full-time for camp
A11: Lead instructor #2 | B11: 30000 | C11: 2 months | D11: =B11*2 | E11: Sports/movement + cooking
A12: Helper / assistant | B12: 18000 | C12: 2 months | D12: =B12*2 | E12: Setup, cleanup, snack prep, supervision
A13: First aid trained person | B13: 12000 | C13: 2 months | D13: =B13*2 | E13: Part-time, on-call during camp hours
A15: MATERIALS (per child per week)
A16: Week 1: Art supplies | B16: 550 | C16: 18 | D16: =B16*C16 | E16: Clay, paint, canvas, brushes, tie-dye kit
A17: Week 2: Science kits | B17: 500 | C17: 18 | D17: =B17*C17 | E17: Baking soda, magnets, slime ingredients, seed kits
A18: Week 3: Cooking ingredients | B18: 450 | C18: 18 | D18: =B18*C18 | E18: Fruits, oats, honey, lemonade supplies
A19: Week 4: Nature supplies | B19: 300 | C19: 18 | D19: =B19*C19 | E19: Bug hotel materials, pressed flower supplies, journals
A20: Week 5: Robot building | B20: 600 | C20: 18 | D20: =B20*C20 | E20: Cardboard, foil, LEDs, tubes, coding cards
A21: Week 6: Market supplies | B21: 450 | C21: 18 | D21: =B21*C21 | E21: Craft materials for products, signage, play money
A22: Week 7: Exhibition | B22: 700 | C22: 18 | D22: =B22*C22 | E22: Frames, labels, certificates, scrapbooks, t-shirts
A24: FOOD & SNACKS
A25: Daily snacks (fruit + juice) | B25: 55 | C25: 18 kids × 35 days | D25: =B25*18*35 | E25: ₹30/child/day
A27: MARKETING
A28: Flyers & posters printing | B28: 5000 | C28: 1 | D28: =B28 | E28: 200 flyers + 20 posters
A29: Instagram promoted posts | B29: 10000 | C29: 1 | D29: =B29 | E29: Optional — boost 2-3 posts
A31: OPERATIONS
A32: Insurance | B32: 12000 | C32: 1 | D32: =B32 | E32: Group activity insurance for 7 weeks
A33: First aid kit + supplies | B33: 5000 | C33: 1 | D33: =B33 | E33: Comprehensive kit
A34: Certificates printing | B34: 200 | C34: 18 | D34: =B34*C34 | E34: Custom designed, heavy stock
A35: Name tags + lanyards | B35: 120 | C35: 18 | D35: =B35*C35 | E35: Printed, durable
A36: Camp t-shirts | B36: 450 | C36: 18 | D36: =B36*C36 | E36: Custom printed, given in Week 7
A37: Scrapbooks | B37: 300 | C37: 18 | D37: =B37*C37 | E37: Blank hardcover, given in Week 7
A39: MISCELLANEOUS
A40: Buffer (10% of above) | D40: =SUM(D6:D37)*0.1 | E40: Unexpected costs, replacements, extras
A42: TOTAL COSTS | D42: =SUM(D6:D37)+D40

Sheet P&L Summary
A1: THE SUMMER CLUB — P&L SUMMARY
B3: Conservative (12 kids) | C3: Target (18 kids) | D3: Stretch (24 kids)
A4: Revenue | B4: =Revenue!B20 | C4: =Revenue!C20 | D4: =Revenue!D20
A6: Fixed Costs
A7: Venue | B7: =Costs!D6+Costs!D7 | C7: =Costs!D6+Costs!D7 | D7: =Costs!D6+Costs!D7
A8: Staff | B8: =Costs!D10+Costs!D11+Costs!D12+Costs!D13 | C8: =Costs!D10+Costs!D11+Costs!D12+Costs!D13 | D8: =Costs!D10+Costs!D11+Costs!D12+Costs!D13
A9: Marketing | B9: =Costs!D28+Costs!D29 | C9: =Costs!D28+Costs!D29 | D9: =Costs!D28+Costs!D29
A10: Insurance + ops (fixed) | B10: =Costs!D32+Costs!D33 | C10: =Costs!D32+Costs!D33 | D10: =Costs!D32+Costs!D33
A11: Total Fixed Costs | B11: =SUM(B6:B9) | C11: =SUM(C6:C9) | D11: =SUM(D6:D9)
A13: Variable Costs (per child)
A14: Materials (7 weeks) | B14: =SUM(Costs!D16:Costs!D22)/18*12 | C14: =SUM(Costs!D16:Costs!D22) | D14: =SUM(Costs!D16:Costs!D22)/18*24
A15: Snacks (35 days) | B15: =30*12*35 | C15: =30*18*35 | D15: =30*24*35
A16: T-shirts + scrapbooks + certs + tags | B16: =(350+200+150+100)*12 | C16: =(350+200+150+100)*18 | D16: =(350+200+150+100)*24
A17: Total Variable Costs | B17: =SUM(B13:B15) | C17: =SUM(C13:C15) | D17: =SUM(D13:D15)
A19: Buffer (10%) | B19: =(B10+B16)*0.1 | C19: =(C10+C16)*0.1 | D19: =(D10+D16)*0.1
A21: TOTAL COSTS | B21: =B10+B16+B18 | C21: =C10+C16+C18 | D21: =D10+D16+D18
A23: NET PROFIT / (LOSS) | B23: =B4-B20 | C23: =C4-C20 | D23: =D4-D20
A24: Margin % | B24: =IF(B4>0,B22/B4,0) | C24: =IF(C4>0,C22/C4,0) | D24: =IF(D4>0,D22/D4,0)
A26: PER-CHILD ECONOMICS
A27: Revenue per child | B27: =Revenue!B21 | C27: =Revenue!C21 | D27: =Revenue!D21
A28: Cost per child | B28: =B20/12 | C28: =C20/18 | D28: =D20/24
A29: Margin per child | B29: =B26-B27 | C29: =C26-C27 | D29: =D26-D27
A31: BREAK-EVEN
A32: Break-even # of kids | B32: =ROUNDUP(B10/(Revenue!B21-B16/12),0) | C32: =ROUNDUP(C10/(Revenue!C21-C16/18),0) | D32: =ROUNDUP(D10/(Revenue!D21-D16/24),0)

Sheet Cash Flow
A1: THE SUMMER CLUB — CASH FLOW
A2: Based on target scenario (18 kids)
B4: March (Pre-camp) | C4: April (Weeks 1-3) | D4: May (Weeks 4-7) | E4: June (Wrap-up) | F4: TOTAL
A5: MONEY IN
A6: Registrations received | B6: 0 | C6: 15 | D6: 3 | E6: 0 | F6: =SUM(B6:E6)
A7: Registration revenue | B7: =B6*Revenue!C21 | C7: =C6*Revenue!C21 | D7: =D6*Revenue!C21 | E7: =E6*Revenue!C21 | F7: =SUM(B7:E7)
A8: Total Inflow | B8: =B7 | C8: =C7 | D8: =D7 | E8: =E7 | F8: =SUM(B8:E8)
A10: MONEY OUT
A11: Venue deposit | B11: 20000 | C11: 0 | D11: 0 | E11: -20000 | F11: =SUM(B11:E11)
A12: Venue rent | B12: 0 | C12: 20000 | D12: 20000 | E12: 0 | F12: =SUM(B12:E12)
A13: Staff salaries | B13: 0 | C13: 55000 | D13: 55000 | E13: 0 | F13: =SUM(B13:E13)
A14: Materials — Weeks 1-3 | B14: 15000 | C14: 34650 | D14: 0 | E14: 0 | F14: =SUM(B14:E14)
A15: Materials — Weeks 4-7 | B15: 0 | C15: 0 | D15: 46350 | E15: 0 | F15: =SUM(B15:E15)
A16: Snacks | B16: 0 | C16: 8100 | D16: 10800 | E16: 0 | F16: =SUM(B16:E16)
A17: Marketing | B17: 5000 | C17: 3000 | D17: 0 | E17: 0 | F17: =SUM(B17:E17)
A18: Insurance + ops | B18: 11000 | C18: 3500 | D18: 0 | E18: 0 | F18: =SUM(B18:E18)
A19: T-shirts, certs, scrapbooks | B19: 0 | C19: 0 | D19: 14400 | E19: 0 | F19: =SUM(B19:E19)
A20: Buffer | B20: 2000 | C20: 5000 | D20: 5000 | E20: 0 | F20: =SUM(B20:E20)
A21: Total Outflow | B21: =SUM(B11:B20) | C21: =SUM(C11:C20) | D21: =SUM(D11:D20) | E21: =SUM(E11:E20) | F21: =SUM(B21:E21)
A23: NET CASH FLOW | B23: =B8-B21 | C23: =C8-C21 | D23: =D8-D21 | E23: =E8-E21 | F23: =SUM(B23:E23)
A24: CUMULATIVE BALANCE | B24: =B23 | C24: =B24+C23 | D24: =C24+D23 | E24: =D24+E23 | F24: =SUM(B24:E24)
